telegram.ext.updater - INFO - Received signal 2 (SIGINT), stopping...
telegram.ext.updater - INFO - Received signal 2 (SIGINT), stopping...
telegram.ext.updater - INFO - Received signal 2 (SIGINT), stopping...
telegram.ext.dispatcher - ERROR - An uncaught error was raised while processing the update
Traceback (most recent call last):
  File "/home/ivan/projects/bot/env/lib/python3.5/site-packages/telegram/ext/dispatcher.py", line 279, in process_update
    handler.handle_update(update, self)
  File "/home/ivan/projects/bot/env/lib/python3.5/site-packages/telegram/ext/messagehandler.py", line 169, in handle_update
    return self.callback(dispatcher.bot, update, **optional_args)
  File "/home/ivan/projects/bot/commands.py", line 14, in next_full_moon
    if user_text.startwith('Когда ближайшее полнолуние после'):
AttributeError: 'str' object has no attribute 'startwith'
telegram.ext.updater - INFO - Received signal 2 (SIGINT), stopping...
telegram.ext.updater - INFO - Received signal 2 (SIGINT), stopping...
telegram.ext.updater - INFO - Received signal 2 (SIGINT), stopping...
telegram.ext.updater - INFO - Received signal 2 (SIGINT), stopping...
telegram.ext.updater - INFO - Received signal 2 (SIGINT), stopping...
telegram.ext.updater - INFO - Received signal 2 (SIGINT), stopping...
telegram.ext.updater - INFO - Received signal 2 (SIGINT), stopping...
telegram.ext.dispatcher - ERROR - An uncaught error was raised while processing the update
Traceback (most recent call last):
  File "/home/ivan/projects/bot/env/lib/python3.5/site-packages/telegram/ext/dispatcher.py", line 279, in process_update
    handler.handle_update(update, self)
  File "/home/ivan/projects/bot/env/lib/python3.5/site-packages/telegram/ext/messagehandler.py", line 169, in handle_update
    return self.callback(dispatcher.bot, update, **optional_args)
  File "/home/ivan/projects/bot/commands.py", line 16, in handle_text_message
    update.message.reply_text(calculate(user_text))
  File "/home/ivan/projects/bot/helper.py", line 48, in calculate
    if chunks[-1].isdigit():
IndexError: list index out of range
telegram.ext.updater - INFO - Received signal 2 (SIGINT), stopping...
telegram.ext.updater - INFO - Received signal 2 (SIGINT), stopping...
telegram.ext.dispatcher - ERROR - An uncaught error was raised while processing the update
Traceback (most recent call last):
  File "/home/ivan/projects/bot/env/lib/python3.5/site-packages/telegram/ext/dispatcher.py", line 279, in process_update
    handler.handle_update(update, self)
  File "/home/ivan/projects/bot/env/lib/python3.5/site-packages/telegram/ext/messagehandler.py", line 169, in handle_update
    return self.callback(dispatcher.bot, update, **optional_args)
  File "/home/ivan/projects/bot/commands.py", line 18, in handle_text_message
    update.message.reply_text(calculate_in_words)
  File "/home/ivan/projects/bot/env/lib/python3.5/site-packages/telegram/message.py", line 455, in reply_text
    return self.bot.send_message(self.chat_id, *args, **kwargs)
  File "/home/ivan/projects/bot/env/lib/python3.5/site-packages/telegram/bot.py", line 65, in decorator
    result = func(self, *args, **kwargs)
  File "/home/ivan/projects/bot/env/lib/python3.5/site-packages/telegram/bot.py", line 90, in decorator
    result = self._request.post(url, data, timeout=kwargs.get('timeout'))
  File "/home/ivan/projects/bot/env/lib/python3.5/site-packages/telegram/utils/request.py", line 308, in post
    body=json.dumps(data).encode('utf-8'),
  File "/usr/lib/python3.5/json/__init__.py", line 230, in dumps
    return _default_encoder.encode(obj)
  File "/usr/lib/python3.5/json/encoder.py", line 198, in encode
    chunks = self.iterencode(o, _one_shot=True)
  File "/usr/lib/python3.5/json/encoder.py", line 256, in iterencode
    return _iterencode(o, 0)
  File "/usr/lib/python3.5/json/encoder.py", line 179, in default
    raise TypeError(repr(o) + " is not JSON serializable")
TypeError: <function calculate_in_words at 0x7f35beea2510> is not JSON serializable
telegram.ext.dispatcher - ERROR - An uncaught error was raised while processing the update
Traceback (most recent call last):
  File "/home/ivan/projects/bot/env/lib/python3.5/site-packages/telegram/ext/dispatcher.py", line 279, in process_update
    handler.handle_update(update, self)
  File "/home/ivan/projects/bot/env/lib/python3.5/site-packages/telegram/ext/messagehandler.py", line 169, in handle_update
    return self.callback(dispatcher.bot, update, **optional_args)
  File "/home/ivan/projects/bot/commands.py", line 18, in handle_text_message
    update.message.reply_text(calculate_in_words)
  File "/home/ivan/projects/bot/env/lib/python3.5/site-packages/telegram/message.py", line 455, in reply_text
    return self.bot.send_message(self.chat_id, *args, **kwargs)
  File "/home/ivan/projects/bot/env/lib/python3.5/site-packages/telegram/bot.py", line 65, in decorator
    result = func(self, *args, **kwargs)
  File "/home/ivan/projects/bot/env/lib/python3.5/site-packages/telegram/bot.py", line 90, in decorator
    result = self._request.post(url, data, timeout=kwargs.get('timeout'))
  File "/home/ivan/projects/bot/env/lib/python3.5/site-packages/telegram/utils/request.py", line 308, in post
    body=json.dumps(data).encode('utf-8'),
  File "/usr/lib/python3.5/json/__init__.py", line 230, in dumps
    return _default_encoder.encode(obj)
  File "/usr/lib/python3.5/json/encoder.py", line 198, in encode
    chunks = self.iterencode(o, _one_shot=True)
  File "/usr/lib/python3.5/json/encoder.py", line 256, in iterencode
    return _iterencode(o, 0)
  File "/usr/lib/python3.5/json/encoder.py", line 179, in default
    raise TypeError(repr(o) + " is not JSON serializable")
TypeError: <function calculate_in_words at 0x7f35beea2510> is not JSON serializable
telegram.ext.updater - INFO - Received signal 2 (SIGINT), stopping...
telegram.ext.updater - INFO - Received signal 2 (SIGINT), stopping...
telegram.ext.dispatcher - ERROR - An uncaught error was raised while processing the update
Traceback (most recent call last):
  File "/home/ivan/projects/bot/env/lib/python3.5/site-packages/telegram/ext/dispatcher.py", line 279, in process_update
    handler.handle_update(update, self)
  File "/home/ivan/projects/bot/env/lib/python3.5/site-packages/telegram/ext/messagehandler.py", line 169, in handle_update
    return self.callback(dispatcher.bot, update, **optional_args)
  File "/home/ivan/projects/bot/commands.py", line 18, in handle_text_message
    update.message.reply_text(calculate_in_words(user_text))
  File "/home/ivan/projects/bot/helper.py", line 89, in calculate_in_words
    return int(numbers_dict[words[2]]) * int(numbers_dict[words[5]])
KeyError: '2'
telegram.ext.updater - INFO - Received signal 2 (SIGINT), stopping...
telegram.ext.updater - INFO - Received signal 2 (SIGINT), stopping...
